2024-02-06 04:51:28,988 - uvicorn.error - ERROR - Exception in ASGI application
  + Exception Group Traceback (most recent call last):
  |   File "/usr/local/lib/python3.9/site-packages/starlette/_utils.py", line 85, in collapse_excgroups
  |     yield
  |   File "/usr/local/lib/python3.9/site-packages/starlette/middleware/base.py", line 193, in __call__
  |     response_sent.set()
  |   File "/usr/local/lib/python3.9/site-packages/anyio/_backends/_asyncio.py", line 678, in __aexit__
  |     raise BaseExceptionGroup(
  | exceptiongroup.ExceptionGroup: unhandled errors in a TaskGroup (1 sub-exception)
  +-+---------------- 1 ----------------
    | Traceback (most recent call last):
    |   File "/usr/local/lib/python3.9/site-packages/uvicorn/protocols/http/h11_impl.py", line 404, in run_asgi
    |     result = await app(  # type: ignore[func-returns-value]
    |   File "/usr/local/lib/python3.9/site-packages/uvicorn/middleware/proxy_headers.py", line 84, in __call__
    |     return await self.app(scope, receive, send)
    |   File "/usr/local/lib/python3.9/site-packages/fastapi/applications.py", line 1054, in __call__
    |     await super().__call__(scope, receive, send)
    |   File "/usr/local/lib/python3.9/site-packages/starlette/applications.py", line 123, in __call__
    |     await self.middleware_stack(scope, receive, send)
    |   File "/usr/local/lib/python3.9/site-packages/starlette/middleware/errors.py", line 186, in __call__
    |     raise exc
    |   File "/usr/local/lib/python3.9/site-packages/starlette/middleware/errors.py", line 164, in __call__
    |     await self.app(scope, receive, _send)
    |   File "/usr/local/lib/python3.9/site-packages/starlette/middleware/base.py", line 193, in __call__
    |     response_sent.set()
    |   File "/usr/local/lib/python3.9/contextlib.py", line 137, in __exit__
    |     self.gen.throw(typ, value, traceback)
    |   File "/usr/local/lib/python3.9/site-packages/starlette/_utils.py", line 91, in collapse_excgroups
    |     raise exc
    |   File "/usr/local/lib/python3.9/site-packages/starlette/middleware/base.py", line 191, in __call__
    |     response = await self.dispatch_func(request, call_next)
    |   File "/app/app/resource/exception/handler.py", line 39, in dispatch
    |     if ENVIRONMENT == "production":
    | NameError: name 'ENVIRONMENT' is not defined
    +------------------------------------

During handling of the above exception, another exception occurred:

Traceback (most recent call last):
  File "/usr/local/lib/python3.9/site-packages/uvicorn/protocols/http/h11_impl.py", line 404, in run_asgi
    result = await app(  # type: ignore[func-returns-value]
  File "/usr/local/lib/python3.9/site-packages/uvicorn/middleware/proxy_headers.py", line 84, in __call__
    return await self.app(scope, receive, send)
  File "/usr/local/lib/python3.9/site-packages/fastapi/applications.py", line 1054, in __call__
    await super().__call__(scope, receive, send)
  File "/usr/local/lib/python3.9/site-packages/starlette/applications.py", line 123, in __call__
    await self.middleware_stack(scope, receive, send)
  File "/usr/local/lib/python3.9/site-packages/starlette/middleware/errors.py", line 186, in __call__
    raise exc
  File "/usr/local/lib/python3.9/site-packages/starlette/middleware/errors.py", line 164, in __call__
    await self.app(scope, receive, _send)
  File "/usr/local/lib/python3.9/site-packages/starlette/middleware/base.py", line 193, in __call__
    response_sent.set()
  File "/usr/local/lib/python3.9/contextlib.py", line 137, in __exit__
    self.gen.throw(typ, value, traceback)
  File "/usr/local/lib/python3.9/site-packages/starlette/_utils.py", line 91, in collapse_excgroups
    raise exc
  File "/usr/local/lib/python3.9/site-packages/starlette/middleware/base.py", line 191, in __call__
    response = await self.dispatch_func(request, call_next)
  File "/app/app/resource/exception/handler.py", line 39, in dispatch
    if ENVIRONMENT == "production":
NameError: name 'ENVIRONMENT' is not defined
2024-02-06 04:51:33,591 - uvicorn.error - ERROR - Exception in ASGI application
  + Exception Group Traceback (most recent call last):
  |   File "/usr/local/lib/python3.9/site-packages/starlette/_utils.py", line 85, in collapse_excgroups
  |     yield
  |   File "/usr/local/lib/python3.9/site-packages/starlette/middleware/base.py", line 193, in __call__
  |     response_sent.set()
  |   File "/usr/local/lib/python3.9/site-packages/anyio/_backends/_asyncio.py", line 678, in __aexit__
  |     raise BaseExceptionGroup(
  | exceptiongroup.ExceptionGroup: unhandled errors in a TaskGroup (1 sub-exception)
  +-+---------------- 1 ----------------
    | Traceback (most recent call last):
    |   File "/usr/local/lib/python3.9/site-packages/uvicorn/protocols/http/h11_impl.py", line 404, in run_asgi
    |     result = await app(  # type: ignore[func-returns-value]
    |   File "/usr/local/lib/python3.9/site-packages/uvicorn/middleware/proxy_headers.py", line 84, in __call__
    |     return await self.app(scope, receive, send)
    |   File "/usr/local/lib/python3.9/site-packages/fastapi/applications.py", line 1054, in __call__
    |     await super().__call__(scope, receive, send)
    |   File "/usr/local/lib/python3.9/site-packages/starlette/applications.py", line 123, in __call__
    |     await self.middleware_stack(scope, receive, send)
    |   File "/usr/local/lib/python3.9/site-packages/starlette/middleware/errors.py", line 186, in __call__
    |     raise exc
    |   File "/usr/local/lib/python3.9/site-packages/starlette/middleware/errors.py", line 164, in __call__
    |     await self.app(scope, receive, _send)
    |   File "/usr/local/lib/python3.9/site-packages/starlette/middleware/base.py", line 193, in __call__
    |     response_sent.set()
    |   File "/usr/local/lib/python3.9/contextlib.py", line 137, in __exit__
    |     self.gen.throw(typ, value, traceback)
    |   File "/usr/local/lib/python3.9/site-packages/starlette/_utils.py", line 91, in collapse_excgroups
    |     raise exc
    |   File "/usr/local/lib/python3.9/site-packages/starlette/middleware/base.py", line 191, in __call__
    |     response = await self.dispatch_func(request, call_next)
    |   File "/app/app/resource/exception/handler.py", line 39, in dispatch
    |     if ENVIRONMENT == "production":
    | NameError: name 'ENVIRONMENT' is not defined
    +------------------------------------

During handling of the above exception, another exception occurred:

Traceback (most recent call last):
  File "/usr/local/lib/python3.9/site-packages/uvicorn/protocols/http/h11_impl.py", line 404, in run_asgi
    result = await app(  # type: ignore[func-returns-value]
  File "/usr/local/lib/python3.9/site-packages/uvicorn/middleware/proxy_headers.py", line 84, in __call__
    return await self.app(scope, receive, send)
  File "/usr/local/lib/python3.9/site-packages/fastapi/applications.py", line 1054, in __call__
    await super().__call__(scope, receive, send)
  File "/usr/local/lib/python3.9/site-packages/starlette/applications.py", line 123, in __call__
    await self.middleware_stack(scope, receive, send)
  File "/usr/local/lib/python3.9/site-packages/starlette/middleware/errors.py", line 186, in __call__
    raise exc
  File "/usr/local/lib/python3.9/site-packages/starlette/middleware/errors.py", line 164, in __call__
    await self.app(scope, receive, _send)
  File "/usr/local/lib/python3.9/site-packages/starlette/middleware/base.py", line 193, in __call__
    response_sent.set()
  File "/usr/local/lib/python3.9/contextlib.py", line 137, in __exit__
    self.gen.throw(typ, value, traceback)
  File "/usr/local/lib/python3.9/site-packages/starlette/_utils.py", line 91, in collapse_excgroups
    raise exc
  File "/usr/local/lib/python3.9/site-packages/starlette/middleware/base.py", line 191, in __call__
    response = await self.dispatch_func(request, call_next)
  File "/app/app/resource/exception/handler.py", line 39, in dispatch
    if ENVIRONMENT == "production":
NameError: name 'ENVIRONMENT' is not defined
