2024-02-06 05:57:29,555 - app.exception - ERROR - Unhandled exception: __aenter__
2024-02-06 05:57:29,557 - app.exception - ERROR - Reversed traceback: AttributeError: __aenter__
  File "/app/app/resource/repository/user_repository.py", line 14, in email_exist
    async with get_db() as session:
  File "/app/app/resource/service/auth_service.py", line 14, in email_exist
    return await self.repository.email_exist(email)
  File "/app/app/resource/controller/auth_controller.py", line 22, in email_exists
    result = await service.email_exist(mail)
  File "/usr/local/lib/python3.9/site-packages/fastapi/routing.py", line 191, in run_endpoint_function
    return await dependant.call(**values)
  File "/usr/local/lib/python3.9/site-packages/fastapi/routing.py", line 294, in app
    raw_response = await run_endpoint_function(
  File "/usr/local/lib/python3.9/site-packages/fastapi/routing.py", line 299, in app
    raise e
  File "/usr/local/lib/python3.9/site-packages/starlette/routing.py", line 72, in app
    response = await func(request)
  File "/usr/local/lib/python3.9/site-packages/starlette/_exception_handler.py", line 53, in wrapped_app
    await app(scope, receive, sender)
  File "/usr/local/lib/python3.9/site-packages/starlette/_exception_handler.py", line 64, in wrapped_app
    raise exc
  File "/usr/local/lib/python3.9/site-packages/starlette/routing.py", line 77, in app
    await wrap_app_handling_exceptions(app, request)(scope, receive, send)
  File "/usr/local/lib/python3.9/site-packages/starlette/routing.py", line 297, in handle
    await self.app(scope, receive, send)
  File "/usr/local/lib/python3.9/site-packages/starlette/routing.py", line 782, in app
    await route.handle(scope, receive, send)
  File "/usr/local/lib/python3.9/site-packages/starlette/routing.py", line 762, in __call__
    await self.middleware_stack(scope, receive, send)
  File "/usr/local/lib/python3.9/site-packages/starlette/_exception_handler.py", line 53, in wrapped_app
    await app(scope, receive, sender)
  File "/usr/local/lib/python3.9/site-packages/starlette/_exception_handler.py", line 64, in wrapped_app
    raise exc
  File "/usr/local/lib/python3.9/site-packages/starlette/middleware/exceptions.py", line 62, in __call__
    await wrap_app_handling_exceptions(self.app, conn)(scope, receive, send)
  File "/usr/local/lib/python3.9/site-packages/starlette/middleware/base.py", line 151, in coro
    await self.app(scope, receive_or_disconnect, send_no_error)
  File "/usr/local/lib/python3.9/site-packages/starlette/middleware/base.py", line 165, in call_next
    raise app_exc
  File "/app/app/resource/exception/handler.py", line 30, in dispatch
    response = await call_next(request)
Traceback (most recent call last):

During handling of the above exception, another exception occurred:

anyio.EndOfStream
  File "/usr/local/lib/python3.9/site-packages/anyio/streams/memory.py", line 112, in receive
    raise EndOfStream
  File "/usr/local/lib/python3.9/site-packages/starlette/middleware/base.py", line 159, in call_next
    message = await recv_stream.receive()
Traceback (most recent call last):

During handling of the above exception, another exception occurred:

anyio.WouldBlock
  File "/usr/local/lib/python3.9/site-packages/anyio/streams/memory.py", line 92, in receive_nowait
    raise WouldBlock
  File "/usr/local/lib/python3.9/site-packages/anyio/streams/memory.py", line 97, in receive
    return self.receive_nowait()
Traceback (most recent call last):

2024-02-06 05:57:29,559 - app.exception - ERROR - Request path: /email-exists, Method: POST
2024-02-06 05:59:22,012 - app.exception - ERROR - Unhandled exception: __aenter__
2024-02-06 05:59:22,023 - app.exception - ERROR - Reversed traceback: AttributeError: __aenter__
  File "/app/app/resource/repository/user_repository.py", line 14, in email_exist
    async with get_db() as session:  # これが正しいコンテキストマネージャの使用法
  File "/app/app/resource/service/auth_service.py", line 14, in email_exist
    return await self.repository.email_exist(email)
  File "/app/app/resource/controller/auth_controller.py", line 22, in email_exists
    result = await service.email_exist(mail)
  File "/usr/local/lib/python3.9/site-packages/fastapi/routing.py", line 191, in run_endpoint_function
    return await dependant.call(**values)
  File "/usr/local/lib/python3.9/site-packages/fastapi/routing.py", line 294, in app
    raw_response = await run_endpoint_function(
  File "/usr/local/lib/python3.9/site-packages/fastapi/routing.py", line 299, in app
    raise e
  File "/usr/local/lib/python3.9/site-packages/starlette/routing.py", line 72, in app
    response = await func(request)
  File "/usr/local/lib/python3.9/site-packages/starlette/_exception_handler.py", line 53, in wrapped_app
    await app(scope, receive, sender)
  File "/usr/local/lib/python3.9/site-packages/starlette/_exception_handler.py", line 64, in wrapped_app
    raise exc
  File "/usr/local/lib/python3.9/site-packages/starlette/routing.py", line 77, in app
    await wrap_app_handling_exceptions(app, request)(scope, receive, send)
  File "/usr/local/lib/python3.9/site-packages/starlette/routing.py", line 297, in handle
    await self.app(scope, receive, send)
  File "/usr/local/lib/python3.9/site-packages/starlette/routing.py", line 782, in app
    await route.handle(scope, receive, send)
  File "/usr/local/lib/python3.9/site-packages/starlette/routing.py", line 762, in __call__
    await self.middleware_stack(scope, receive, send)
  File "/usr/local/lib/python3.9/site-packages/starlette/_exception_handler.py", line 53, in wrapped_app
    await app(scope, receive, sender)
  File "/usr/local/lib/python3.9/site-packages/starlette/_exception_handler.py", line 64, in wrapped_app
    raise exc
  File "/usr/local/lib/python3.9/site-packages/starlette/middleware/exceptions.py", line 62, in __call__
    await wrap_app_handling_exceptions(self.app, conn)(scope, receive, send)
  File "/usr/local/lib/python3.9/site-packages/starlette/middleware/base.py", line 151, in coro
    await self.app(scope, receive_or_disconnect, send_no_error)
  File "/usr/local/lib/python3.9/site-packages/starlette/middleware/base.py", line 165, in call_next
    raise app_exc
  File "/app/app/resource/exception/handler.py", line 30, in dispatch
    response = await call_next(request)
Traceback (most recent call last):

During handling of the above exception, another exception occurred:

anyio.EndOfStream
  File "/usr/local/lib/python3.9/site-packages/anyio/streams/memory.py", line 112, in receive
    raise EndOfStream
  File "/usr/local/lib/python3.9/site-packages/starlette/middleware/base.py", line 159, in call_next
    message = await recv_stream.receive()
Traceback (most recent call last):

During handling of the above exception, another exception occurred:

anyio.WouldBlock
  File "/usr/local/lib/python3.9/site-packages/anyio/streams/memory.py", line 92, in receive_nowait
    raise WouldBlock
  File "/usr/local/lib/python3.9/site-packages/anyio/streams/memory.py", line 97, in receive
    return self.receive_nowait()
Traceback (most recent call last):

2024-02-06 05:59:22,024 - app.exception - ERROR - Request path: /email-exists, Method: POST
2024-02-06 06:04:40,153 - app.exception - ERROR - Unhandled exception: __aenter__
2024-02-06 06:04:40,161 - app.exception - ERROR - Reversed traceback: AttributeError: __aenter__
  File "/app/app/resource/repository/user_repository.py", line 14, in email_exist
    async with get_db() as session:
  File "/app/app/resource/service/auth_service.py", line 14, in email_exist
    return await self.repository.email_exist(email)
  File "/app/app/resource/controller/auth_controller.py", line 22, in email_exists
    result = await service.email_exist(mail)
  File "/usr/local/lib/python3.9/site-packages/fastapi/routing.py", line 191, in run_endpoint_function
    return await dependant.call(**values)
  File "/usr/local/lib/python3.9/site-packages/fastapi/routing.py", line 294, in app
    raw_response = await run_endpoint_function(
  File "/usr/local/lib/python3.9/site-packages/fastapi/routing.py", line 299, in app
    raise e
  File "/usr/local/lib/python3.9/site-packages/starlette/routing.py", line 72, in app
    response = await func(request)
  File "/usr/local/lib/python3.9/site-packages/starlette/_exception_handler.py", line 53, in wrapped_app
    await app(scope, receive, sender)
  File "/usr/local/lib/python3.9/site-packages/starlette/_exception_handler.py", line 64, in wrapped_app
    raise exc
  File "/usr/local/lib/python3.9/site-packages/starlette/routing.py", line 77, in app
    await wrap_app_handling_exceptions(app, request)(scope, receive, send)
  File "/usr/local/lib/python3.9/site-packages/starlette/routing.py", line 297, in handle
    await self.app(scope, receive, send)
  File "/usr/local/lib/python3.9/site-packages/starlette/routing.py", line 782, in app
    await route.handle(scope, receive, send)
  File "/usr/local/lib/python3.9/site-packages/starlette/routing.py", line 762, in __call__
    await self.middleware_stack(scope, receive, send)
  File "/usr/local/lib/python3.9/site-packages/starlette/_exception_handler.py", line 53, in wrapped_app
    await app(scope, receive, sender)
  File "/usr/local/lib/python3.9/site-packages/starlette/_exception_handler.py", line 64, in wrapped_app
    raise exc
  File "/usr/local/lib/python3.9/site-packages/starlette/middleware/exceptions.py", line 62, in __call__
    await wrap_app_handling_exceptions(self.app, conn)(scope, receive, send)
  File "/usr/local/lib/python3.9/site-packages/starlette/middleware/base.py", line 151, in coro
    await self.app(scope, receive_or_disconnect, send_no_error)
  File "/usr/local/lib/python3.9/site-packages/starlette/middleware/base.py", line 165, in call_next
    raise app_exc
  File "/app/app/resource/exception/handler.py", line 30, in dispatch
    response = await call_next(request)
Traceback (most recent call last):

During handling of the above exception, another exception occurred:

anyio.EndOfStream
  File "/usr/local/lib/python3.9/site-packages/anyio/streams/memory.py", line 112, in receive
    raise EndOfStream
  File "/usr/local/lib/python3.9/site-packages/starlette/middleware/base.py", line 159, in call_next
    message = await recv_stream.receive()
Traceback (most recent call last):

During handling of the above exception, another exception occurred:

anyio.WouldBlock
  File "/usr/local/lib/python3.9/site-packages/anyio/streams/memory.py", line 92, in receive_nowait
    raise WouldBlock
  File "/usr/local/lib/python3.9/site-packages/anyio/streams/memory.py", line 97, in receive
    return self.receive_nowait()
Traceback (most recent call last):

2024-02-06 06:04:40,163 - app.exception - ERROR - Request path: /email-exists, Method: POST
2024-02-06 06:06:11,275 - app.exception - ERROR - Unhandled exception: badly formed hexadecimal UUID string
2024-02-06 06:06:11,288 - app.exception - ERROR - Reversed traceback: ValueError: badly formed hexadecimal UUID string
  File "/usr/local/lib/python3.9/uuid.py", line 177, in __init__
    raise ValueError('badly formed hexadecimal UUID string')
  File "/usr/local/lib/python3.9/site-packages/sqlalchemy_utils/types/uuid.py", line 113, in process_result_value
    return uuid.UUID(bytes=value) if self.binary else uuid.UUID(value)
  File "/usr/local/lib/python3.9/site-packages/sqlalchemy/sql/type_api.py", line 2129, in process
    return fixed_process_value(value, dialect)
  File "lib/sqlalchemy/cyextension/resultproxy.pyx", line 79, in sqlalchemy.cyextension.resultproxy._apply_processors
  File "lib/sqlalchemy/cyextension/resultproxy.pyx", line 22, in sqlalchemy.cyextension.resultproxy.BaseRow.__init__
  File "/usr/local/lib/python3.9/site-packages/sqlalchemy/engine/result.py", line 544, in <listcomp>
    return [make_row(row) for row in rows]
  File "/usr/local/lib/python3.9/site-packages/sqlalchemy/engine/result.py", line 544, in _raw_all_rows
    return [make_row(row) for row in rows]
  File "/usr/local/lib/python3.9/site-packages/sqlalchemy/orm/loading.py", line 217, in chunks
    fetch = cursor._raw_all_rows()
  File "/usr/local/lib/python3.9/site-packages/sqlalchemy/orm/loading.py", line 259, in instances
    _prebuffered = list(chunks(None))
  File "/usr/local/lib/python3.9/site-packages/sqlalchemy/orm/context.py", line 589, in orm_setup_cursor_result
    return loading.instances(result, querycontext)
  File "/usr/local/lib/python3.9/site-packages/sqlalchemy/orm/context.py", line 296, in orm_execute_statement
    return cls.orm_setup_cursor_result(
  File "/usr/local/lib/python3.9/site-packages/sqlalchemy/orm/session.py", line 2190, in _execute_internal
    result: Result[Any] = compile_state_cls.orm_execute_statement(
  File "/usr/local/lib/python3.9/site-packages/sqlalchemy/orm/session.py", line 2308, in execute
    return self._execute_internal(
  File "/usr/local/lib/python3.9/site-packages/sqlalchemy/util/_concurrency_py3k.py", line 202, in greenlet_spawn
    result = context.switch(value)
  File "/usr/local/lib/python3.9/site-packages/sqlalchemy/ext/asyncio/session.py", line 455, in execute
    result = await greenlet_spawn(
  File "/app/app/resource/repository/user_repository.py", line 15, in email_exist
    result = await session.execute(select(User).filter(User.email == email))
  File "/app/app/resource/service/auth_service.py", line 14, in email_exist
    return await self.repository.email_exist(email)
  File "/app/app/resource/controller/auth_controller.py", line 22, in email_exists
    result = await service.email_exist(mail)
  File "/usr/local/lib/python3.9/site-packages/fastapi/routing.py", line 191, in run_endpoint_function
    return await dependant.call(**values)
  File "/usr/local/lib/python3.9/site-packages/fastapi/routing.py", line 294, in app
    raw_response = await run_endpoint_function(
  File "/usr/local/lib/python3.9/site-packages/fastapi/routing.py", line 299, in app
    raise e
  File "/usr/local/lib/python3.9/site-packages/starlette/routing.py", line 72, in app
    response = await func(request)
  File "/usr/local/lib/python3.9/site-packages/starlette/_exception_handler.py", line 53, in wrapped_app
    await app(scope, receive, sender)
  File "/usr/local/lib/python3.9/site-packages/starlette/_exception_handler.py", line 64, in wrapped_app
    raise exc
  File "/usr/local/lib/python3.9/site-packages/starlette/routing.py", line 77, in app
    await wrap_app_handling_exceptions(app, request)(scope, receive, send)
  File "/usr/local/lib/python3.9/site-packages/starlette/routing.py", line 297, in handle
    await self.app(scope, receive, send)
  File "/usr/local/lib/python3.9/site-packages/starlette/routing.py", line 782, in app
    await route.handle(scope, receive, send)
  File "/usr/local/lib/python3.9/site-packages/starlette/routing.py", line 762, in __call__
    await self.middleware_stack(scope, receive, send)
  File "/usr/local/lib/python3.9/site-packages/starlette/_exception_handler.py", line 53, in wrapped_app
    await app(scope, receive, sender)
  File "/usr/local/lib/python3.9/site-packages/starlette/_exception_handler.py", line 64, in wrapped_app
    raise exc
  File "/usr/local/lib/python3.9/site-packages/starlette/middleware/exceptions.py", line 62, in __call__
    await wrap_app_handling_exceptions(self.app, conn)(scope, receive, send)
  File "/usr/local/lib/python3.9/site-packages/starlette/middleware/base.py", line 151, in coro
    await self.app(scope, receive_or_disconnect, send_no_error)
  File "/usr/local/lib/python3.9/site-packages/starlette/middleware/base.py", line 165, in call_next
    raise app_exc
  File "/app/app/resource/exception/handler.py", line 30, in dispatch
    response = await call_next(request)
Traceback (most recent call last):

During handling of the above exception, another exception occurred:

anyio.EndOfStream
  File "/usr/local/lib/python3.9/site-packages/anyio/streams/memory.py", line 112, in receive
    raise EndOfStream
  File "/usr/local/lib/python3.9/site-packages/starlette/middleware/base.py", line 159, in call_next
    message = await recv_stream.receive()
Traceback (most recent call last):

During handling of the above exception, another exception occurred:

anyio.WouldBlock
  File "/usr/local/lib/python3.9/site-packages/anyio/streams/memory.py", line 92, in receive_nowait
    raise WouldBlock
  File "/usr/local/lib/python3.9/site-packages/anyio/streams/memory.py", line 97, in receive
    return self.receive_nowait()
Traceback (most recent call last):

2024-02-06 06:06:11,289 - app.exception - ERROR - Request path: /email-exists, Method: POST
2024-02-06 06:08:59,912 - app.exception - ERROR - Unhandled exception: invalid literal for int() with base 16: 'a1b2c3d4e5f6g7h8i9j0k1l2m3n4o5p6'
2024-02-06 06:08:59,922 - app.exception - ERROR - Reversed traceback: ValueError: invalid literal for int() with base 16: 'a1b2c3d4e5f6g7h8i9j0k1l2m3n4o5p6'
  File "/usr/local/lib/python3.9/uuid.py", line 178, in __init__
    int = int_(hex, 16)
  File "/usr/local/lib/python3.9/site-packages/sqlalchemy_utils/types/uuid.py", line 113, in process_result_value
    return uuid.UUID(bytes=value) if self.binary else uuid.UUID(value)
  File "/usr/local/lib/python3.9/site-packages/sqlalchemy/sql/type_api.py", line 2129, in process
    return fixed_process_value(value, dialect)
  File "lib/sqlalchemy/cyextension/resultproxy.pyx", line 79, in sqlalchemy.cyextension.resultproxy._apply_processors
  File "lib/sqlalchemy/cyextension/resultproxy.pyx", line 22, in sqlalchemy.cyextension.resultproxy.BaseRow.__init__
  File "/usr/local/lib/python3.9/site-packages/sqlalchemy/engine/result.py", line 544, in <listcomp>
    return [make_row(row) for row in rows]
  File "/usr/local/lib/python3.9/site-packages/sqlalchemy/engine/result.py", line 544, in _raw_all_rows
    return [make_row(row) for row in rows]
  File "/usr/local/lib/python3.9/site-packages/sqlalchemy/orm/loading.py", line 217, in chunks
    fetch = cursor._raw_all_rows()
  File "/usr/local/lib/python3.9/site-packages/sqlalchemy/orm/loading.py", line 259, in instances
    _prebuffered = list(chunks(None))
  File "/usr/local/lib/python3.9/site-packages/sqlalchemy/orm/context.py", line 589, in orm_setup_cursor_result
    return loading.instances(result, querycontext)
  File "/usr/local/lib/python3.9/site-packages/sqlalchemy/orm/context.py", line 296, in orm_execute_statement
    return cls.orm_setup_cursor_result(
  File "/usr/local/lib/python3.9/site-packages/sqlalchemy/orm/session.py", line 2190, in _execute_internal
    result: Result[Any] = compile_state_cls.orm_execute_statement(
  File "/usr/local/lib/python3.9/site-packages/sqlalchemy/orm/session.py", line 2308, in execute
    return self._execute_internal(
  File "/usr/local/lib/python3.9/site-packages/sqlalchemy/util/_concurrency_py3k.py", line 202, in greenlet_spawn
    result = context.switch(value)
  File "/usr/local/lib/python3.9/site-packages/sqlalchemy/ext/asyncio/session.py", line 455, in execute
    result = await greenlet_spawn(
  File "/app/app/resource/repository/user_repository.py", line 15, in email_exist
    result = await session.execute(select(User).filter(User.email == email))
  File "/app/app/resource/service/auth_service.py", line 14, in email_exist
    return await self.repository.email_exist(email)
  File "/app/app/resource/controller/auth_controller.py", line 22, in email_exists
    result = await service.email_exist(mail)
  File "/usr/local/lib/python3.9/site-packages/fastapi/routing.py", line 191, in run_endpoint_function
    return await dependant.call(**values)
  File "/usr/local/lib/python3.9/site-packages/fastapi/routing.py", line 294, in app
    raw_response = await run_endpoint_function(
  File "/usr/local/lib/python3.9/site-packages/fastapi/routing.py", line 299, in app
    raise e
  File "/usr/local/lib/python3.9/site-packages/starlette/routing.py", line 72, in app
    response = await func(request)
  File "/usr/local/lib/python3.9/site-packages/starlette/_exception_handler.py", line 53, in wrapped_app
    await app(scope, receive, sender)
  File "/usr/local/lib/python3.9/site-packages/starlette/_exception_handler.py", line 64, in wrapped_app
    raise exc
  File "/usr/local/lib/python3.9/site-packages/starlette/routing.py", line 77, in app
    await wrap_app_handling_exceptions(app, request)(scope, receive, send)
  File "/usr/local/lib/python3.9/site-packages/starlette/routing.py", line 297, in handle
    await self.app(scope, receive, send)
  File "/usr/local/lib/python3.9/site-packages/starlette/routing.py", line 782, in app
    await route.handle(scope, receive, send)
  File "/usr/local/lib/python3.9/site-packages/starlette/routing.py", line 762, in __call__
    await self.middleware_stack(scope, receive, send)
  File "/usr/local/lib/python3.9/site-packages/starlette/_exception_handler.py", line 53, in wrapped_app
    await app(scope, receive, sender)
  File "/usr/local/lib/python3.9/site-packages/starlette/_exception_handler.py", line 64, in wrapped_app
    raise exc
  File "/usr/local/lib/python3.9/site-packages/starlette/middleware/exceptions.py", line 62, in __call__
    await wrap_app_handling_exceptions(self.app, conn)(scope, receive, send)
  File "/usr/local/lib/python3.9/site-packages/starlette/middleware/base.py", line 151, in coro
    await self.app(scope, receive_or_disconnect, send_no_error)
  File "/usr/local/lib/python3.9/site-packages/starlette/middleware/base.py", line 165, in call_next
    raise app_exc
  File "/app/app/resource/exception/handler.py", line 30, in dispatch
    response = await call_next(request)
Traceback (most recent call last):

During handling of the above exception, another exception occurred:

anyio.EndOfStream
  File "/usr/local/lib/python3.9/site-packages/anyio/streams/memory.py", line 112, in receive
    raise EndOfStream
  File "/usr/local/lib/python3.9/site-packages/starlette/middleware/base.py", line 159, in call_next
    message = await recv_stream.receive()
Traceback (most recent call last):

During handling of the above exception, another exception occurred:

anyio.WouldBlock
  File "/usr/local/lib/python3.9/site-packages/anyio/streams/memory.py", line 92, in receive_nowait
    raise WouldBlock
  File "/usr/local/lib/python3.9/site-packages/anyio/streams/memory.py", line 97, in receive
    return self.receive_nowait()
Traceback (most recent call last):

2024-02-06 06:08:59,924 - app.exception - ERROR - Request path: /email-exists, Method: POST
2024-02-06 06:09:27,907 - app.exception - ERROR - Unhandled exception: invalid literal for int() with base 16: 'a1b2c3d4e5f6g7h8i9j0k1l2m3n4o5p6'
2024-02-06 06:09:27,914 - app.exception - ERROR - Reversed traceback: ValueError: invalid literal for int() with base 16: 'a1b2c3d4e5f6g7h8i9j0k1l2m3n4o5p6'
  File "/usr/local/lib/python3.9/uuid.py", line 178, in __init__
    int = int_(hex, 16)
  File "/usr/local/lib/python3.9/site-packages/sqlalchemy_utils/types/uuid.py", line 113, in process_result_value
    return uuid.UUID(bytes=value) if self.binary else uuid.UUID(value)
  File "/usr/local/lib/python3.9/site-packages/sqlalchemy/sql/type_api.py", line 2129, in process
    return fixed_process_value(value, dialect)
  File "lib/sqlalchemy/cyextension/resultproxy.pyx", line 79, in sqlalchemy.cyextension.resultproxy._apply_processors
  File "lib/sqlalchemy/cyextension/resultproxy.pyx", line 22, in sqlalchemy.cyextension.resultproxy.BaseRow.__init__
  File "/usr/local/lib/python3.9/site-packages/sqlalchemy/engine/result.py", line 544, in <listcomp>
    return [make_row(row) for row in rows]
  File "/usr/local/lib/python3.9/site-packages/sqlalchemy/engine/result.py", line 544, in _raw_all_rows
    return [make_row(row) for row in rows]
  File "/usr/local/lib/python3.9/site-packages/sqlalchemy/orm/loading.py", line 217, in chunks
    fetch = cursor._raw_all_rows()
  File "/usr/local/lib/python3.9/site-packages/sqlalchemy/orm/loading.py", line 259, in instances
    _prebuffered = list(chunks(None))
  File "/usr/local/lib/python3.9/site-packages/sqlalchemy/orm/context.py", line 589, in orm_setup_cursor_result
    return loading.instances(result, querycontext)
  File "/usr/local/lib/python3.9/site-packages/sqlalchemy/orm/context.py", line 296, in orm_execute_statement
    return cls.orm_setup_cursor_result(
  File "/usr/local/lib/python3.9/site-packages/sqlalchemy/orm/session.py", line 2190, in _execute_internal
    result: Result[Any] = compile_state_cls.orm_execute_statement(
  File "/usr/local/lib/python3.9/site-packages/sqlalchemy/orm/session.py", line 2308, in execute
    return self._execute_internal(
  File "/usr/local/lib/python3.9/site-packages/sqlalchemy/util/_concurrency_py3k.py", line 202, in greenlet_spawn
    result = context.switch(value)
  File "/usr/local/lib/python3.9/site-packages/sqlalchemy/ext/asyncio/session.py", line 455, in execute
    result = await greenlet_spawn(
  File "/app/app/resource/repository/user_repository.py", line 15, in email_exist
    result = await session.execute(select(User).filter(User.email == email))
  File "/app/app/resource/service/auth_service.py", line 14, in email_exist
    return await self.repository.email_exist(email)
  File "/app/app/resource/controller/auth_controller.py", line 22, in email_exists
    result = await service.email_exist(mail)
  File "/usr/local/lib/python3.9/site-packages/fastapi/routing.py", line 191, in run_endpoint_function
    return await dependant.call(**values)
  File "/usr/local/lib/python3.9/site-packages/fastapi/routing.py", line 294, in app
    raw_response = await run_endpoint_function(
  File "/usr/local/lib/python3.9/site-packages/fastapi/routing.py", line 299, in app
    raise e
  File "/usr/local/lib/python3.9/site-packages/starlette/routing.py", line 72, in app
    response = await func(request)
  File "/usr/local/lib/python3.9/site-packages/starlette/_exception_handler.py", line 53, in wrapped_app
    await app(scope, receive, sender)
  File "/usr/local/lib/python3.9/site-packages/starlette/_exception_handler.py", line 64, in wrapped_app
    raise exc
  File "/usr/local/lib/python3.9/site-packages/starlette/routing.py", line 77, in app
    await wrap_app_handling_exceptions(app, request)(scope, receive, send)
  File "/usr/local/lib/python3.9/site-packages/starlette/routing.py", line 297, in handle
    await self.app(scope, receive, send)
  File "/usr/local/lib/python3.9/site-packages/starlette/routing.py", line 782, in app
    await route.handle(scope, receive, send)
  File "/usr/local/lib/python3.9/site-packages/starlette/routing.py", line 762, in __call__
    await self.middleware_stack(scope, receive, send)
  File "/usr/local/lib/python3.9/site-packages/starlette/_exception_handler.py", line 53, in wrapped_app
    await app(scope, receive, sender)
  File "/usr/local/lib/python3.9/site-packages/starlette/_exception_handler.py", line 64, in wrapped_app
    raise exc
  File "/usr/local/lib/python3.9/site-packages/starlette/middleware/exceptions.py", line 62, in __call__
    await wrap_app_handling_exceptions(self.app, conn)(scope, receive, send)
  File "/usr/local/lib/python3.9/site-packages/starlette/middleware/base.py", line 151, in coro
    await self.app(scope, receive_or_disconnect, send_no_error)
  File "/usr/local/lib/python3.9/site-packages/starlette/middleware/base.py", line 165, in call_next
    raise app_exc
  File "/app/app/resource/exception/handler.py", line 30, in dispatch
    response = await call_next(request)
Traceback (most recent call last):

During handling of the above exception, another exception occurred:

anyio.EndOfStream
  File "/usr/local/lib/python3.9/site-packages/anyio/streams/memory.py", line 112, in receive
    raise EndOfStream
  File "/usr/local/lib/python3.9/site-packages/starlette/middleware/base.py", line 159, in call_next
    message = await recv_stream.receive()
Traceback (most recent call last):

During handling of the above exception, another exception occurred:

anyio.WouldBlock
  File "/usr/local/lib/python3.9/site-packages/anyio/streams/memory.py", line 92, in receive_nowait
    raise WouldBlock
  File "/usr/local/lib/python3.9/site-packages/anyio/streams/memory.py", line 97, in receive
    return self.receive_nowait()
Traceback (most recent call last):

2024-02-06 06:09:27,918 - app.exception - ERROR - Request path: /email-exists, Method: POST
2024-02-06 06:10:30,076 - app.exception - ERROR - Unhandled exception: invalid literal for int() with base 16: 'a1b2c3d4e5f6g7h8i9j0k1l2m3n4o5p6'
2024-02-06 06:10:30,086 - app.exception - ERROR - Reversed traceback: ValueError: invalid literal for int() with base 16: 'a1b2c3d4e5f6g7h8i9j0k1l2m3n4o5p6'
  File "/usr/local/lib/python3.9/uuid.py", line 178, in __init__
    int = int_(hex, 16)
  File "/usr/local/lib/python3.9/site-packages/sqlalchemy_utils/types/uuid.py", line 113, in process_result_value
    return uuid.UUID(bytes=value) if self.binary else uuid.UUID(value)
  File "/usr/local/lib/python3.9/site-packages/sqlalchemy/sql/type_api.py", line 2129, in process
    return fixed_process_value(value, dialect)
  File "lib/sqlalchemy/cyextension/resultproxy.pyx", line 79, in sqlalchemy.cyextension.resultproxy._apply_processors
  File "lib/sqlalchemy/cyextension/resultproxy.pyx", line 22, in sqlalchemy.cyextension.resultproxy.BaseRow.__init__
  File "/usr/local/lib/python3.9/site-packages/sqlalchemy/engine/result.py", line 544, in <listcomp>
    return [make_row(row) for row in rows]
  File "/usr/local/lib/python3.9/site-packages/sqlalchemy/engine/result.py", line 544, in _raw_all_rows
    return [make_row(row) for row in rows]
  File "/usr/local/lib/python3.9/site-packages/sqlalchemy/orm/loading.py", line 217, in chunks
    fetch = cursor._raw_all_rows()
  File "/usr/local/lib/python3.9/site-packages/sqlalchemy/orm/loading.py", line 259, in instances
    _prebuffered = list(chunks(None))
  File "/usr/local/lib/python3.9/site-packages/sqlalchemy/orm/context.py", line 589, in orm_setup_cursor_result
    return loading.instances(result, querycontext)
  File "/usr/local/lib/python3.9/site-packages/sqlalchemy/orm/context.py", line 296, in orm_execute_statement
    return cls.orm_setup_cursor_result(
  File "/usr/local/lib/python3.9/site-packages/sqlalchemy/orm/session.py", line 2190, in _execute_internal
    result: Result[Any] = compile_state_cls.orm_execute_statement(
  File "/usr/local/lib/python3.9/site-packages/sqlalchemy/orm/session.py", line 2308, in execute
    return self._execute_internal(
  File "/usr/local/lib/python3.9/site-packages/sqlalchemy/util/_concurrency_py3k.py", line 202, in greenlet_spawn
    result = context.switch(value)
  File "/usr/local/lib/python3.9/site-packages/sqlalchemy/ext/asyncio/session.py", line 455, in execute
    result = await greenlet_spawn(
  File "/app/app/resource/repository/user_repository.py", line 15, in email_exist
    result = await session.execute(select(User).filter(User.email == email))
  File "/app/app/resource/service/auth_service.py", line 14, in email_exist
    return await self.repository.email_exist(email)
  File "/app/app/resource/controller/auth_controller.py", line 22, in email_exists
    result = await service.email_exist(mail)
  File "/usr/local/lib/python3.9/site-packages/fastapi/routing.py", line 191, in run_endpoint_function
    return await dependant.call(**values)
  File "/usr/local/lib/python3.9/site-packages/fastapi/routing.py", line 294, in app
    raw_response = await run_endpoint_function(
  File "/usr/local/lib/python3.9/site-packages/fastapi/routing.py", line 299, in app
    raise e
  File "/usr/local/lib/python3.9/site-packages/starlette/routing.py", line 72, in app
    response = await func(request)
  File "/usr/local/lib/python3.9/site-packages/starlette/_exception_handler.py", line 53, in wrapped_app
    await app(scope, receive, sender)
  File "/usr/local/lib/python3.9/site-packages/starlette/_exception_handler.py", line 64, in wrapped_app
    raise exc
  File "/usr/local/lib/python3.9/site-packages/starlette/routing.py", line 77, in app
    await wrap_app_handling_exceptions(app, request)(scope, receive, send)
  File "/usr/local/lib/python3.9/site-packages/starlette/routing.py", line 297, in handle
    await self.app(scope, receive, send)
  File "/usr/local/lib/python3.9/site-packages/starlette/routing.py", line 782, in app
    await route.handle(scope, receive, send)
  File "/usr/local/lib/python3.9/site-packages/starlette/routing.py", line 762, in __call__
    await self.middleware_stack(scope, receive, send)
  File "/usr/local/lib/python3.9/site-packages/starlette/_exception_handler.py", line 53, in wrapped_app
    await app(scope, receive, sender)
  File "/usr/local/lib/python3.9/site-packages/starlette/_exception_handler.py", line 64, in wrapped_app
    raise exc
  File "/usr/local/lib/python3.9/site-packages/starlette/middleware/exceptions.py", line 62, in __call__
    await wrap_app_handling_exceptions(self.app, conn)(scope, receive, send)
  File "/usr/local/lib/python3.9/site-packages/starlette/middleware/base.py", line 151, in coro
    await self.app(scope, receive_or_disconnect, send_no_error)
  File "/usr/local/lib/python3.9/site-packages/starlette/middleware/base.py", line 165, in call_next
    raise app_exc
  File "/app/app/resource/exception/handler.py", line 30, in dispatch
    response = await call_next(request)
Traceback (most recent call last):

During handling of the above exception, another exception occurred:

anyio.EndOfStream
  File "/usr/local/lib/python3.9/site-packages/anyio/streams/memory.py", line 112, in receive
    raise EndOfStream
  File "/usr/local/lib/python3.9/site-packages/starlette/middleware/base.py", line 159, in call_next
    message = await recv_stream.receive()
Traceback (most recent call last):

During handling of the above exception, another exception occurred:

anyio.WouldBlock
  File "/usr/local/lib/python3.9/site-packages/anyio/streams/memory.py", line 92, in receive_nowait
    raise WouldBlock
  File "/usr/local/lib/python3.9/site-packages/anyio/streams/memory.py", line 97, in receive
    return self.receive_nowait()
Traceback (most recent call last):

2024-02-06 06:10:30,088 - app.exception - ERROR - Request path: /email-exists, Method: POST
2024-02-06 06:13:08,126 - app.exception - ERROR - Unhandled exception: bytes is not a 16-char string
2024-02-06 06:13:08,139 - app.exception - ERROR - Reversed traceback: ValueError: bytes is not a 16-char string
  File "/usr/local/lib/python3.9/uuid.py", line 186, in __init__
    raise ValueError('bytes is not a 16-char string')
  File "/usr/local/lib/python3.9/site-packages/sqlalchemy_utils/types/uuid.py", line 113, in process_result_value
    return uuid.UUID(bytes=value) if self.binary else uuid.UUID(value)
  File "/usr/local/lib/python3.9/site-packages/sqlalchemy/sql/type_api.py", line 2129, in process
    return fixed_process_value(value, dialect)
  File "lib/sqlalchemy/cyextension/resultproxy.pyx", line 79, in sqlalchemy.cyextension.resultproxy._apply_processors
  File "lib/sqlalchemy/cyextension/resultproxy.pyx", line 22, in sqlalchemy.cyextension.resultproxy.BaseRow.__init__
  File "/usr/local/lib/python3.9/site-packages/sqlalchemy/engine/result.py", line 544, in <listcomp>
    return [make_row(row) for row in rows]
  File "/usr/local/lib/python3.9/site-packages/sqlalchemy/engine/result.py", line 544, in _raw_all_rows
    return [make_row(row) for row in rows]
  File "/usr/local/lib/python3.9/site-packages/sqlalchemy/orm/loading.py", line 217, in chunks
    fetch = cursor._raw_all_rows()
  File "/usr/local/lib/python3.9/site-packages/sqlalchemy/orm/loading.py", line 259, in instances
    _prebuffered = list(chunks(None))
  File "/usr/local/lib/python3.9/site-packages/sqlalchemy/orm/context.py", line 589, in orm_setup_cursor_result
    return loading.instances(result, querycontext)
  File "/usr/local/lib/python3.9/site-packages/sqlalchemy/orm/context.py", line 296, in orm_execute_statement
    return cls.orm_setup_cursor_result(
  File "/usr/local/lib/python3.9/site-packages/sqlalchemy/orm/session.py", line 2190, in _execute_internal
    result: Result[Any] = compile_state_cls.orm_execute_statement(
  File "/usr/local/lib/python3.9/site-packages/sqlalchemy/orm/session.py", line 2308, in execute
    return self._execute_internal(
  File "/usr/local/lib/python3.9/site-packages/sqlalchemy/util/_concurrency_py3k.py", line 202, in greenlet_spawn
    result = context.switch(value)
  File "/usr/local/lib/python3.9/site-packages/sqlalchemy/ext/asyncio/session.py", line 455, in execute
    result = await greenlet_spawn(
  File "/app/app/resource/repository/user_repository.py", line 15, in email_exist
    result = await session.execute(select(User).filter(User.email == email))
  File "/app/app/resource/service/auth_service.py", line 14, in email_exist
    return await self.repository.email_exist(email)
  File "/app/app/resource/controller/auth_controller.py", line 22, in email_exists
    result = await service.email_exist(mail)
  File "/usr/local/lib/python3.9/site-packages/fastapi/routing.py", line 191, in run_endpoint_function
    return await dependant.call(**values)
  File "/usr/local/lib/python3.9/site-packages/fastapi/routing.py", line 294, in app
    raw_response = await run_endpoint_function(
  File "/usr/local/lib/python3.9/site-packages/fastapi/routing.py", line 299, in app
    raise e
  File "/usr/local/lib/python3.9/site-packages/starlette/routing.py", line 72, in app
    response = await func(request)
  File "/usr/local/lib/python3.9/site-packages/starlette/_exception_handler.py", line 53, in wrapped_app
    await app(scope, receive, sender)
  File "/usr/local/lib/python3.9/site-packages/starlette/_exception_handler.py", line 64, in wrapped_app
    raise exc
  File "/usr/local/lib/python3.9/site-packages/starlette/routing.py", line 77, in app
    await wrap_app_handling_exceptions(app, request)(scope, receive, send)
  File "/usr/local/lib/python3.9/site-packages/starlette/routing.py", line 297, in handle
    await self.app(scope, receive, send)
  File "/usr/local/lib/python3.9/site-packages/starlette/routing.py", line 782, in app
    await route.handle(scope, receive, send)
  File "/usr/local/lib/python3.9/site-packages/starlette/routing.py", line 762, in __call__
    await self.middleware_stack(scope, receive, send)
  File "/usr/local/lib/python3.9/site-packages/starlette/_exception_handler.py", line 53, in wrapped_app
    await app(scope, receive, sender)
  File "/usr/local/lib/python3.9/site-packages/starlette/_exception_handler.py", line 64, in wrapped_app
    raise exc
  File "/usr/local/lib/python3.9/site-packages/starlette/middleware/exceptions.py", line 62, in __call__
    await wrap_app_handling_exceptions(self.app, conn)(scope, receive, send)
  File "/usr/local/lib/python3.9/site-packages/starlette/middleware/base.py", line 151, in coro
    await self.app(scope, receive_or_disconnect, send_no_error)
  File "/usr/local/lib/python3.9/site-packages/starlette/middleware/base.py", line 165, in call_next
    raise app_exc
  File "/app/app/resource/exception/handler.py", line 30, in dispatch
    response = await call_next(request)
Traceback (most recent call last):

During handling of the above exception, another exception occurred:

anyio.EndOfStream
  File "/usr/local/lib/python3.9/site-packages/anyio/streams/memory.py", line 112, in receive
    raise EndOfStream
  File "/usr/local/lib/python3.9/site-packages/starlette/middleware/base.py", line 159, in call_next
    message = await recv_stream.receive()
Traceback (most recent call last):

During handling of the above exception, another exception occurred:

anyio.WouldBlock
  File "/usr/local/lib/python3.9/site-packages/anyio/streams/memory.py", line 92, in receive_nowait
    raise WouldBlock
  File "/usr/local/lib/python3.9/site-packages/anyio/streams/memory.py", line 97, in receive
    return self.receive_nowait()
Traceback (most recent call last):

2024-02-06 06:13:08,141 - app.exception - ERROR - Request path: /email-exists, Method: POST
2024-02-06 06:13:37,891 - app.exception - ERROR - Unhandled exception: bytes is not a 16-char string
2024-02-06 06:13:37,903 - app.exception - ERROR - Reversed traceback: ValueError: bytes is not a 16-char string
  File "/usr/local/lib/python3.9/uuid.py", line 186, in __init__
    raise ValueError('bytes is not a 16-char string')
  File "/usr/local/lib/python3.9/site-packages/sqlalchemy_utils/types/uuid.py", line 113, in process_result_value
    return uuid.UUID(bytes=value) if self.binary else uuid.UUID(value)
  File "/usr/local/lib/python3.9/site-packages/sqlalchemy/sql/type_api.py", line 2129, in process
    return fixed_process_value(value, dialect)
  File "lib/sqlalchemy/cyextension/resultproxy.pyx", line 79, in sqlalchemy.cyextension.resultproxy._apply_processors
  File "lib/sqlalchemy/cyextension/resultproxy.pyx", line 22, in sqlalchemy.cyextension.resultproxy.BaseRow.__init__
  File "/usr/local/lib/python3.9/site-packages/sqlalchemy/engine/result.py", line 544, in <listcomp>
    return [make_row(row) for row in rows]
  File "/usr/local/lib/python3.9/site-packages/sqlalchemy/engine/result.py", line 544, in _raw_all_rows
    return [make_row(row) for row in rows]
  File "/usr/local/lib/python3.9/site-packages/sqlalchemy/orm/loading.py", line 217, in chunks
    fetch = cursor._raw_all_rows()
  File "/usr/local/lib/python3.9/site-packages/sqlalchemy/orm/loading.py", line 259, in instances
    _prebuffered = list(chunks(None))
  File "/usr/local/lib/python3.9/site-packages/sqlalchemy/orm/context.py", line 589, in orm_setup_cursor_result
    return loading.instances(result, querycontext)
  File "/usr/local/lib/python3.9/site-packages/sqlalchemy/orm/context.py", line 296, in orm_execute_statement
    return cls.orm_setup_cursor_result(
  File "/usr/local/lib/python3.9/site-packages/sqlalchemy/orm/session.py", line 2190, in _execute_internal
    result: Result[Any] = compile_state_cls.orm_execute_statement(
  File "/usr/local/lib/python3.9/site-packages/sqlalchemy/orm/session.py", line 2308, in execute
    return self._execute_internal(
  File "/usr/local/lib/python3.9/site-packages/sqlalchemy/util/_concurrency_py3k.py", line 202, in greenlet_spawn
    result = context.switch(value)
  File "/usr/local/lib/python3.9/site-packages/sqlalchemy/ext/asyncio/session.py", line 455, in execute
    result = await greenlet_spawn(
  File "/app/app/resource/repository/user_repository.py", line 15, in email_exist
    result = await session.execute(select(User).filter(User.email == email))
  File "/app/app/resource/service/auth_service.py", line 14, in email_exist
    return await self.repository.email_exist(email)
  File "/app/app/resource/controller/auth_controller.py", line 22, in email_exists
    result = await service.email_exist(mail)
  File "/usr/local/lib/python3.9/site-packages/fastapi/routing.py", line 191, in run_endpoint_function
    return await dependant.call(**values)
  File "/usr/local/lib/python3.9/site-packages/fastapi/routing.py", line 294, in app
    raw_response = await run_endpoint_function(
  File "/usr/local/lib/python3.9/site-packages/fastapi/routing.py", line 299, in app
    raise e
  File "/usr/local/lib/python3.9/site-packages/starlette/routing.py", line 72, in app
    response = await func(request)
  File "/usr/local/lib/python3.9/site-packages/starlette/_exception_handler.py", line 53, in wrapped_app
    await app(scope, receive, sender)
  File "/usr/local/lib/python3.9/site-packages/starlette/_exception_handler.py", line 64, in wrapped_app
    raise exc
  File "/usr/local/lib/python3.9/site-packages/starlette/routing.py", line 77, in app
    await wrap_app_handling_exceptions(app, request)(scope, receive, send)
  File "/usr/local/lib/python3.9/site-packages/starlette/routing.py", line 297, in handle
    await self.app(scope, receive, send)
  File "/usr/local/lib/python3.9/site-packages/starlette/routing.py", line 782, in app
    await route.handle(scope, receive, send)
  File "/usr/local/lib/python3.9/site-packages/starlette/routing.py", line 762, in __call__
    await self.middleware_stack(scope, receive, send)
  File "/usr/local/lib/python3.9/site-packages/starlette/_exception_handler.py", line 53, in wrapped_app
    await app(scope, receive, sender)
  File "/usr/local/lib/python3.9/site-packages/starlette/_exception_handler.py", line 64, in wrapped_app
    raise exc
  File "/usr/local/lib/python3.9/site-packages/starlette/middleware/exceptions.py", line 62, in __call__
    await wrap_app_handling_exceptions(self.app, conn)(scope, receive, send)
  File "/usr/local/lib/python3.9/site-packages/starlette/middleware/base.py", line 151, in coro
    await self.app(scope, receive_or_disconnect, send_no_error)
  File "/usr/local/lib/python3.9/site-packages/starlette/middleware/base.py", line 165, in call_next
    raise app_exc
  File "/app/app/resource/exception/handler.py", line 30, in dispatch
    response = await call_next(request)
Traceback (most recent call last):

During handling of the above exception, another exception occurred:

anyio.EndOfStream
  File "/usr/local/lib/python3.9/site-packages/anyio/streams/memory.py", line 112, in receive
    raise EndOfStream
  File "/usr/local/lib/python3.9/site-packages/starlette/middleware/base.py", line 159, in call_next
    message = await recv_stream.receive()
Traceback (most recent call last):

During handling of the above exception, another exception occurred:

anyio.WouldBlock
  File "/usr/local/lib/python3.9/site-packages/anyio/streams/memory.py", line 92, in receive_nowait
    raise WouldBlock
  File "/usr/local/lib/python3.9/site-packages/anyio/streams/memory.py", line 97, in receive
    return self.receive_nowait()
Traceback (most recent call last):

2024-02-06 06:13:37,904 - app.exception - ERROR - Request path: /email-exists, Method: POST
2024-02-06 06:13:37,976 - app.exception - ERROR - Unhandled exception: bytes is not a 16-char string
2024-02-06 06:13:37,980 - app.exception - ERROR - Reversed traceback: ValueError: bytes is not a 16-char string
  File "/usr/local/lib/python3.9/uuid.py", line 186, in __init__
    raise ValueError('bytes is not a 16-char string')
  File "/usr/local/lib/python3.9/site-packages/sqlalchemy_utils/types/uuid.py", line 113, in process_result_value
    return uuid.UUID(bytes=value) if self.binary else uuid.UUID(value)
  File "/usr/local/lib/python3.9/site-packages/sqlalchemy/sql/type_api.py", line 2129, in process
    return fixed_process_value(value, dialect)
  File "lib/sqlalchemy/cyextension/resultproxy.pyx", line 79, in sqlalchemy.cyextension.resultproxy._apply_processors
  File "lib/sqlalchemy/cyextension/resultproxy.pyx", line 22, in sqlalchemy.cyextension.resultproxy.BaseRow.__init__
  File "/usr/local/lib/python3.9/site-packages/sqlalchemy/engine/result.py", line 544, in <listcomp>
    return [make_row(row) for row in rows]
  File "/usr/local/lib/python3.9/site-packages/sqlalchemy/engine/result.py", line 544, in _raw_all_rows
    return [make_row(row) for row in rows]
  File "/usr/local/lib/python3.9/site-packages/sqlalchemy/orm/loading.py", line 217, in chunks
    fetch = cursor._raw_all_rows()
  File "/usr/local/lib/python3.9/site-packages/sqlalchemy/orm/loading.py", line 259, in instances
    _prebuffered = list(chunks(None))
  File "/usr/local/lib/python3.9/site-packages/sqlalchemy/orm/context.py", line 589, in orm_setup_cursor_result
    return loading.instances(result, querycontext)
  File "/usr/local/lib/python3.9/site-packages/sqlalchemy/orm/context.py", line 296, in orm_execute_statement
    return cls.orm_setup_cursor_result(
  File "/usr/local/lib/python3.9/site-packages/sqlalchemy/orm/session.py", line 2190, in _execute_internal
    result: Result[Any] = compile_state_cls.orm_execute_statement(
  File "/usr/local/lib/python3.9/site-packages/sqlalchemy/orm/session.py", line 2308, in execute
    return self._execute_internal(
  File "/usr/local/lib/python3.9/site-packages/sqlalchemy/util/_concurrency_py3k.py", line 202, in greenlet_spawn
    result = context.switch(value)
  File "/usr/local/lib/python3.9/site-packages/sqlalchemy/ext/asyncio/session.py", line 455, in execute
    result = await greenlet_spawn(
  File "/app/app/resource/repository/user_repository.py", line 15, in email_exist
    result = await session.execute(select(User).filter(User.email == email))
  File "/app/app/resource/service/auth_service.py", line 14, in email_exist
    return await self.repository.email_exist(email)
  File "/app/app/resource/controller/auth_controller.py", line 22, in email_exists
    result = await service.email_exist(mail)
  File "/usr/local/lib/python3.9/site-packages/fastapi/routing.py", line 191, in run_endpoint_function
    return await dependant.call(**values)
  File "/usr/local/lib/python3.9/site-packages/fastapi/routing.py", line 294, in app
    raw_response = await run_endpoint_function(
  File "/usr/local/lib/python3.9/site-packages/fastapi/routing.py", line 299, in app
    raise e
  File "/usr/local/lib/python3.9/site-packages/starlette/routing.py", line 72, in app
    response = await func(request)
  File "/usr/local/lib/python3.9/site-packages/starlette/_exception_handler.py", line 53, in wrapped_app
    await app(scope, receive, sender)
  File "/usr/local/lib/python3.9/site-packages/starlette/_exception_handler.py", line 64, in wrapped_app
    raise exc
  File "/usr/local/lib/python3.9/site-packages/starlette/routing.py", line 77, in app
    await wrap_app_handling_exceptions(app, request)(scope, receive, send)
  File "/usr/local/lib/python3.9/site-packages/starlette/routing.py", line 297, in handle
    await self.app(scope, receive, send)
  File "/usr/local/lib/python3.9/site-packages/starlette/routing.py", line 782, in app
    await route.handle(scope, receive, send)
  File "/usr/local/lib/python3.9/site-packages/starlette/routing.py", line 762, in __call__
    await self.middleware_stack(scope, receive, send)
  File "/usr/local/lib/python3.9/site-packages/starlette/_exception_handler.py", line 53, in wrapped_app
    await app(scope, receive, sender)
  File "/usr/local/lib/python3.9/site-packages/starlette/_exception_handler.py", line 64, in wrapped_app
    raise exc
  File "/usr/local/lib/python3.9/site-packages/starlette/middleware/exceptions.py", line 62, in __call__
    await wrap_app_handling_exceptions(self.app, conn)(scope, receive, send)
  File "/usr/local/lib/python3.9/site-packages/starlette/middleware/base.py", line 151, in coro
    await self.app(scope, receive_or_disconnect, send_no_error)
  File "/usr/local/lib/python3.9/site-packages/starlette/middleware/base.py", line 165, in call_next
    raise app_exc
  File "/app/app/resource/exception/handler.py", line 30, in dispatch
    response = await call_next(request)
Traceback (most recent call last):

During handling of the above exception, another exception occurred:

anyio.EndOfStream
  File "/usr/local/lib/python3.9/site-packages/anyio/streams/memory.py", line 112, in receive
    raise EndOfStream
  File "/usr/local/lib/python3.9/site-packages/starlette/middleware/base.py", line 159, in call_next
    message = await recv_stream.receive()
Traceback (most recent call last):

During handling of the above exception, another exception occurred:

anyio.WouldBlock
  File "/usr/local/lib/python3.9/site-packages/anyio/streams/memory.py", line 92, in receive_nowait
    raise WouldBlock
  File "/usr/local/lib/python3.9/site-packages/anyio/streams/memory.py", line 97, in receive
    return self.receive_nowait()
Traceback (most recent call last):

2024-02-06 06:13:37,981 - app.exception - ERROR - Request path: /email-exists, Method: POST
2024-02-06 06:14:42,226 - app.exception - ERROR - Unhandled exception: bytes is not a 16-char string
2024-02-06 06:14:42,238 - app.exception - ERROR - Reversed traceback: ValueError: bytes is not a 16-char string
  File "/usr/local/lib/python3.9/uuid.py", line 186, in __init__
    raise ValueError('bytes is not a 16-char string')
  File "/usr/local/lib/python3.9/site-packages/sqlalchemy_utils/types/uuid.py", line 113, in process_result_value
    return uuid.UUID(bytes=value) if self.binary else uuid.UUID(value)
  File "/usr/local/lib/python3.9/site-packages/sqlalchemy/sql/type_api.py", line 2129, in process
    return fixed_process_value(value, dialect)
  File "lib/sqlalchemy/cyextension/resultproxy.pyx", line 79, in sqlalchemy.cyextension.resultproxy._apply_processors
  File "lib/sqlalchemy/cyextension/resultproxy.pyx", line 22, in sqlalchemy.cyextension.resultproxy.BaseRow.__init__
  File "/usr/local/lib/python3.9/site-packages/sqlalchemy/engine/result.py", line 544, in <listcomp>
    return [make_row(row) for row in rows]
  File "/usr/local/lib/python3.9/site-packages/sqlalchemy/engine/result.py", line 544, in _raw_all_rows
    return [make_row(row) for row in rows]
  File "/usr/local/lib/python3.9/site-packages/sqlalchemy/orm/loading.py", line 217, in chunks
    fetch = cursor._raw_all_rows()
  File "/usr/local/lib/python3.9/site-packages/sqlalchemy/orm/loading.py", line 259, in instances
    _prebuffered = list(chunks(None))
  File "/usr/local/lib/python3.9/site-packages/sqlalchemy/orm/context.py", line 589, in orm_setup_cursor_result
    return loading.instances(result, querycontext)
  File "/usr/local/lib/python3.9/site-packages/sqlalchemy/orm/context.py", line 296, in orm_execute_statement
    return cls.orm_setup_cursor_result(
  File "/usr/local/lib/python3.9/site-packages/sqlalchemy/orm/session.py", line 2190, in _execute_internal
    result: Result[Any] = compile_state_cls.orm_execute_statement(
  File "/usr/local/lib/python3.9/site-packages/sqlalchemy/orm/session.py", line 2308, in execute
    return self._execute_internal(
  File "/usr/local/lib/python3.9/site-packages/sqlalchemy/util/_concurrency_py3k.py", line 202, in greenlet_spawn
    result = context.switch(value)
  File "/usr/local/lib/python3.9/site-packages/sqlalchemy/ext/asyncio/session.py", line 455, in execute
    result = await greenlet_spawn(
  File "/app/app/resource/repository/user_repository.py", line 15, in email_exist
    result = await session.execute(select(User).filter(User.email == email))
  File "/app/app/resource/service/auth_service.py", line 14, in email_exist
    return await self.repository.email_exist(email)
  File "/app/app/resource/controller/auth_controller.py", line 22, in email_exists
    result = await service.email_exist(mail)
  File "/usr/local/lib/python3.9/site-packages/fastapi/routing.py", line 191, in run_endpoint_function
    return await dependant.call(**values)
  File "/usr/local/lib/python3.9/site-packages/fastapi/routing.py", line 294, in app
    raw_response = await run_endpoint_function(
  File "/usr/local/lib/python3.9/site-packages/fastapi/routing.py", line 299, in app
    raise e
  File "/usr/local/lib/python3.9/site-packages/starlette/routing.py", line 72, in app
    response = await func(request)
  File "/usr/local/lib/python3.9/site-packages/starlette/_exception_handler.py", line 53, in wrapped_app
    await app(scope, receive, sender)
  File "/usr/local/lib/python3.9/site-packages/starlette/_exception_handler.py", line 64, in wrapped_app
    raise exc
  File "/usr/local/lib/python3.9/site-packages/starlette/routing.py", line 77, in app
    await wrap_app_handling_exceptions(app, request)(scope, receive, send)
  File "/usr/local/lib/python3.9/site-packages/starlette/routing.py", line 297, in handle
    await self.app(scope, receive, send)
  File "/usr/local/lib/python3.9/site-packages/starlette/routing.py", line 782, in app
    await route.handle(scope, receive, send)
  File "/usr/local/lib/python3.9/site-packages/starlette/routing.py", line 762, in __call__
    await self.middleware_stack(scope, receive, send)
  File "/usr/local/lib/python3.9/site-packages/starlette/_exception_handler.py", line 53, in wrapped_app
    await app(scope, receive, sender)
  File "/usr/local/lib/python3.9/site-packages/starlette/_exception_handler.py", line 64, in wrapped_app
    raise exc
  File "/usr/local/lib/python3.9/site-packages/starlette/middleware/exceptions.py", line 62, in __call__
    await wrap_app_handling_exceptions(self.app, conn)(scope, receive, send)
  File "/usr/local/lib/python3.9/site-packages/starlette/middleware/base.py", line 151, in coro
    await self.app(scope, receive_or_disconnect, send_no_error)
  File "/usr/local/lib/python3.9/site-packages/starlette/middleware/base.py", line 165, in call_next
    raise app_exc
  File "/app/app/resource/exception/handler.py", line 30, in dispatch
    response = await call_next(request)
Traceback (most recent call last):

During handling of the above exception, another exception occurred:

anyio.EndOfStream
  File "/usr/local/lib/python3.9/site-packages/anyio/streams/memory.py", line 112, in receive
    raise EndOfStream
  File "/usr/local/lib/python3.9/site-packages/starlette/middleware/base.py", line 159, in call_next
    message = await recv_stream.receive()
Traceback (most recent call last):

During handling of the above exception, another exception occurred:

anyio.WouldBlock
  File "/usr/local/lib/python3.9/site-packages/anyio/streams/memory.py", line 92, in receive_nowait
    raise WouldBlock
  File "/usr/local/lib/python3.9/site-packages/anyio/streams/memory.py", line 97, in receive
    return self.receive_nowait()
Traceback (most recent call last):

2024-02-06 06:14:42,240 - app.exception - ERROR - Request path: /email-exists, Method: POST
2024-02-06 06:15:55,010 - app.exception - ERROR - Unhandled exception: bytes is not a 16-char string
2024-02-06 06:15:55,020 - app.exception - ERROR - Reversed traceback: ValueError: bytes is not a 16-char string
  File "/usr/local/lib/python3.9/uuid.py", line 186, in __init__
    raise ValueError('bytes is not a 16-char string')
  File "/usr/local/lib/python3.9/site-packages/sqlalchemy_utils/types/uuid.py", line 113, in process_result_value
    return uuid.UUID(bytes=value) if self.binary else uuid.UUID(value)
  File "/usr/local/lib/python3.9/site-packages/sqlalchemy/sql/type_api.py", line 2129, in process
    return fixed_process_value(value, dialect)
  File "lib/sqlalchemy/cyextension/resultproxy.pyx", line 79, in sqlalchemy.cyextension.resultproxy._apply_processors
  File "lib/sqlalchemy/cyextension/resultproxy.pyx", line 22, in sqlalchemy.cyextension.resultproxy.BaseRow.__init__
  File "/usr/local/lib/python3.9/site-packages/sqlalchemy/engine/result.py", line 544, in <listcomp>
    return [make_row(row) for row in rows]
  File "/usr/local/lib/python3.9/site-packages/sqlalchemy/engine/result.py", line 544, in _raw_all_rows
    return [make_row(row) for row in rows]
  File "/usr/local/lib/python3.9/site-packages/sqlalchemy/orm/loading.py", line 217, in chunks
    fetch = cursor._raw_all_rows()
  File "/usr/local/lib/python3.9/site-packages/sqlalchemy/orm/loading.py", line 259, in instances
    _prebuffered = list(chunks(None))
  File "/usr/local/lib/python3.9/site-packages/sqlalchemy/orm/context.py", line 589, in orm_setup_cursor_result
    return loading.instances(result, querycontext)
  File "/usr/local/lib/python3.9/site-packages/sqlalchemy/orm/context.py", line 296, in orm_execute_statement
    return cls.orm_setup_cursor_result(
  File "/usr/local/lib/python3.9/site-packages/sqlalchemy/orm/session.py", line 2190, in _execute_internal
    result: Result[Any] = compile_state_cls.orm_execute_statement(
  File "/usr/local/lib/python3.9/site-packages/sqlalchemy/orm/session.py", line 2308, in execute
    return self._execute_internal(
  File "/usr/local/lib/python3.9/site-packages/sqlalchemy/util/_concurrency_py3k.py", line 202, in greenlet_spawn
    result = context.switch(value)
  File "/usr/local/lib/python3.9/site-packages/sqlalchemy/ext/asyncio/session.py", line 455, in execute
    result = await greenlet_spawn(
  File "/app/app/resource/repository/user_repository.py", line 15, in email_exist
    result = await session.execute(select(User).filter(User.email == email))
  File "/app/app/resource/service/auth_service.py", line 14, in email_exist
    return await self.repository.email_exist(email)
  File "/app/app/resource/controller/auth_controller.py", line 22, in email_exists
    result = await service.email_exist(mail)
  File "/usr/local/lib/python3.9/site-packages/fastapi/routing.py", line 191, in run_endpoint_function
    return await dependant.call(**values)
  File "/usr/local/lib/python3.9/site-packages/fastapi/routing.py", line 294, in app
    raw_response = await run_endpoint_function(
  File "/usr/local/lib/python3.9/site-packages/fastapi/routing.py", line 299, in app
    raise e
  File "/usr/local/lib/python3.9/site-packages/starlette/routing.py", line 72, in app
    response = await func(request)
  File "/usr/local/lib/python3.9/site-packages/starlette/_exception_handler.py", line 53, in wrapped_app
    await app(scope, receive, sender)
  File "/usr/local/lib/python3.9/site-packages/starlette/_exception_handler.py", line 64, in wrapped_app
    raise exc
  File "/usr/local/lib/python3.9/site-packages/starlette/routing.py", line 77, in app
    await wrap_app_handling_exceptions(app, request)(scope, receive, send)
  File "/usr/local/lib/python3.9/site-packages/starlette/routing.py", line 297, in handle
    await self.app(scope, receive, send)
  File "/usr/local/lib/python3.9/site-packages/starlette/routing.py", line 782, in app
    await route.handle(scope, receive, send)
  File "/usr/local/lib/python3.9/site-packages/starlette/routing.py", line 762, in __call__
    await self.middleware_stack(scope, receive, send)
  File "/usr/local/lib/python3.9/site-packages/starlette/_exception_handler.py", line 53, in wrapped_app
    await app(scope, receive, sender)
  File "/usr/local/lib/python3.9/site-packages/starlette/_exception_handler.py", line 64, in wrapped_app
    raise exc
  File "/usr/local/lib/python3.9/site-packages/starlette/middleware/exceptions.py", line 62, in __call__
    await wrap_app_handling_exceptions(self.app, conn)(scope, receive, send)
  File "/usr/local/lib/python3.9/site-packages/starlette/middleware/base.py", line 151, in coro
    await self.app(scope, receive_or_disconnect, send_no_error)
  File "/usr/local/lib/python3.9/site-packages/starlette/middleware/base.py", line 165, in call_next
    raise app_exc
  File "/app/app/resource/exception/handler.py", line 30, in dispatch
    response = await call_next(request)
Traceback (most recent call last):

During handling of the above exception, another exception occurred:

anyio.EndOfStream
  File "/usr/local/lib/python3.9/site-packages/anyio/streams/memory.py", line 112, in receive
    raise EndOfStream
  File "/usr/local/lib/python3.9/site-packages/starlette/middleware/base.py", line 159, in call_next
    message = await recv_stream.receive()
Traceback (most recent call last):

During handling of the above exception, another exception occurred:

anyio.WouldBlock
  File "/usr/local/lib/python3.9/site-packages/anyio/streams/memory.py", line 92, in receive_nowait
    raise WouldBlock
  File "/usr/local/lib/python3.9/site-packages/anyio/streams/memory.py", line 97, in receive
    return self.receive_nowait()
Traceback (most recent call last):

2024-02-06 06:15:55,022 - app.exception - ERROR - Request path: /email-exists, Method: POST
2024-02-06 14:48:41,864 - app.exception - ERROR - Unhandled exception: 1 validation errors:
  {'type': 'bool_type', 'loc': ('response',), 'msg': 'Input should be a valid boolean', 'input': None, 'url': 'https://errors.pydantic.dev/2.6/v/bool_type'}

2024-02-06 14:48:41,869 - app.exception - ERROR - Reversed traceback: fastapi.exceptions.ResponseValidationError: 1 validation errors:
  {'type': 'bool_type', 'loc': ('response',), 'msg': 'Input should be a valid boolean', 'input': None, 'url': 'https://errors.pydantic.dev/2.6/v/bool_type'}

  File "/usr/local/lib/python3.9/site-packages/fastapi/routing.py", line 155, in serialize_response
    raise ResponseValidationError(
  File "/usr/local/lib/python3.9/site-packages/fastapi/routing.py", line 315, in app
    content = await serialize_response(
  File "/usr/local/lib/python3.9/site-packages/starlette/routing.py", line 72, in app
    response = await func(request)
  File "/usr/local/lib/python3.9/site-packages/starlette/_exception_handler.py", line 53, in wrapped_app
    await app(scope, receive, sender)
  File "/usr/local/lib/python3.9/site-packages/starlette/_exception_handler.py", line 64, in wrapped_app
    raise exc
  File "/usr/local/lib/python3.9/site-packages/starlette/routing.py", line 77, in app
    await wrap_app_handling_exceptions(app, request)(scope, receive, send)
  File "/usr/local/lib/python3.9/site-packages/starlette/routing.py", line 297, in handle
    await self.app(scope, receive, send)
  File "/usr/local/lib/python3.9/site-packages/starlette/routing.py", line 782, in app
    await route.handle(scope, receive, send)
  File "/usr/local/lib/python3.9/site-packages/starlette/routing.py", line 762, in __call__
    await self.middleware_stack(scope, receive, send)
  File "/usr/local/lib/python3.9/site-packages/starlette/_exception_handler.py", line 53, in wrapped_app
    await app(scope, receive, sender)
  File "/usr/local/lib/python3.9/site-packages/starlette/_exception_handler.py", line 64, in wrapped_app
    raise exc
  File "/usr/local/lib/python3.9/site-packages/starlette/middleware/exceptions.py", line 62, in __call__
    await wrap_app_handling_exceptions(self.app, conn)(scope, receive, send)
  File "/usr/local/lib/python3.9/site-packages/starlette/middleware/base.py", line 151, in coro
    await self.app(scope, receive_or_disconnect, send_no_error)
  File "/usr/local/lib/python3.9/site-packages/starlette/middleware/base.py", line 165, in call_next
    raise app_exc
  File "/app/app/resource/exception/handler.py", line 30, in dispatch
    response = await call_next(request)
Traceback (most recent call last):

During handling of the above exception, another exception occurred:

anyio.EndOfStream
  File "/usr/local/lib/python3.9/site-packages/anyio/streams/memory.py", line 112, in receive
    raise EndOfStream
  File "/usr/local/lib/python3.9/site-packages/starlette/middleware/base.py", line 159, in call_next
    message = await recv_stream.receive()
Traceback (most recent call last):

During handling of the above exception, another exception occurred:

anyio.WouldBlock
  File "/usr/local/lib/python3.9/site-packages/anyio/streams/memory.py", line 92, in receive_nowait
    raise WouldBlock
  File "/usr/local/lib/python3.9/site-packages/anyio/streams/memory.py", line 97, in receive
    return self.receive_nowait()
Traceback (most recent call last):

2024-02-06 14:48:41,870 - app.exception - ERROR - Request path: /id-account-exists, Method: POST
2024-02-06 14:48:58,041 - app.exception - ERROR - Unhandled exception: 1 validation errors:
  {'type': 'bool_type', 'loc': ('response',), 'msg': 'Input should be a valid boolean', 'input': None, 'url': 'https://errors.pydantic.dev/2.6/v/bool_type'}

2024-02-06 14:48:58,045 - app.exception - ERROR - Reversed traceback: fastapi.exceptions.ResponseValidationError: 1 validation errors:
  {'type': 'bool_type', 'loc': ('response',), 'msg': 'Input should be a valid boolean', 'input': None, 'url': 'https://errors.pydantic.dev/2.6/v/bool_type'}

  File "/usr/local/lib/python3.9/site-packages/fastapi/routing.py", line 155, in serialize_response
    raise ResponseValidationError(
  File "/usr/local/lib/python3.9/site-packages/fastapi/routing.py", line 315, in app
    content = await serialize_response(
  File "/usr/local/lib/python3.9/site-packages/starlette/routing.py", line 72, in app
    response = await func(request)
  File "/usr/local/lib/python3.9/site-packages/starlette/_exception_handler.py", line 53, in wrapped_app
    await app(scope, receive, sender)
  File "/usr/local/lib/python3.9/site-packages/starlette/_exception_handler.py", line 64, in wrapped_app
    raise exc
  File "/usr/local/lib/python3.9/site-packages/starlette/routing.py", line 77, in app
    await wrap_app_handling_exceptions(app, request)(scope, receive, send)
  File "/usr/local/lib/python3.9/site-packages/starlette/routing.py", line 297, in handle
    await self.app(scope, receive, send)
  File "/usr/local/lib/python3.9/site-packages/starlette/routing.py", line 782, in app
    await route.handle(scope, receive, send)
  File "/usr/local/lib/python3.9/site-packages/starlette/routing.py", line 762, in __call__
    await self.middleware_stack(scope, receive, send)
  File "/usr/local/lib/python3.9/site-packages/starlette/_exception_handler.py", line 53, in wrapped_app
    await app(scope, receive, sender)
  File "/usr/local/lib/python3.9/site-packages/starlette/_exception_handler.py", line 64, in wrapped_app
    raise exc
  File "/usr/local/lib/python3.9/site-packages/starlette/middleware/exceptions.py", line 62, in __call__
    await wrap_app_handling_exceptions(self.app, conn)(scope, receive, send)
  File "/usr/local/lib/python3.9/site-packages/starlette/middleware/base.py", line 151, in coro
    await self.app(scope, receive_or_disconnect, send_no_error)
  File "/usr/local/lib/python3.9/site-packages/starlette/middleware/base.py", line 165, in call_next
    raise app_exc
  File "/app/app/resource/exception/handler.py", line 30, in dispatch
    response = await call_next(request)
Traceback (most recent call last):

During handling of the above exception, another exception occurred:

anyio.EndOfStream
  File "/usr/local/lib/python3.9/site-packages/anyio/streams/memory.py", line 112, in receive
    raise EndOfStream
  File "/usr/local/lib/python3.9/site-packages/starlette/middleware/base.py", line 159, in call_next
    message = await recv_stream.receive()
Traceback (most recent call last):

During handling of the above exception, another exception occurred:

anyio.WouldBlock
  File "/usr/local/lib/python3.9/site-packages/anyio/streams/memory.py", line 92, in receive_nowait
    raise WouldBlock
  File "/usr/local/lib/python3.9/site-packages/anyio/streams/memory.py", line 97, in receive
    return self.receive_nowait()
Traceback (most recent call last):

2024-02-06 14:48:58,046 - app.exception - ERROR - Request path: /id-account-exists, Method: POST
